Workbook
Name Close: 'Progress Report'!$E$14
Name HAZARDS: [1]Hazards!$C$5:$F$311
Name In_Progress: 'Progress Report'!$D$14
Name June: #REF!
Name June: #REF!
Name Months: 'Report Award Reports'!$S$4:$T$22
Name NM: Table1333[]
Name NM: #REF!
Name Open: 'Progress Report'!$C$14
Name Overdue: 'Progress Report'!$F$14
Name PRI: #REF!
Name PRI: #REF!

Sheet Dashboard
B1: A. Finding SOURCES | H1: B. Content
B2: Source | C2: No. Findings | H2: Audit Source | I2: Worksheet Title
B3: CAAK | C3: =COUNTIF(AUDITS!C4:C5000, "CAAK") -> 2 | G3: 1 | H3: Audits & Walkabout | I3: AUDITS
B4: HSSE | C4: =COUNTIF(AUDITS!C:C, "HSSE") -> 14 | G4: 2 | H4: Near Miss Report | I4: NMR
B5: SSCWB | C5: =COUNTIF(AUDITS!C4:C5000, "SSC WB") -> 12 | G5: 3 | H5: Incident Report | I5: IR
B6: NMR | C6: =COUNTIF(NMI!H4:H4953, "Nearmiss") -> 47 | G6: 4 | H6: Electrical Inspection | I6: EI
B7: IR | C7: =COUNTIF(NMI!H4:H4953, "Incident")+COUNTA(IR!A2:A5000) -> 10 | G7: 5 | H7: CAAK | I7: AUDITS
B8: LOD3 E.Insp | C8: =COUNTIF(AUDITS!C4:C5000, "LOD3 E.Insp") -> 5
H9: ="Total number of Audits for 2025 is "&COUNTA(Table3[Audit Date])&"." -> Total number of Audits for 2025 is 5.
B12: A.1. HSSE & ADUITs Findings | E12: A.2. Nearmiss Findings
B13: Item | C13: Counts | E13: Item | F13: Counts
B14: 🔢 Total Findings | C14: =COUNTA(AUDITS!F4:F5000) -> 33 | E14: 🔢 Total Findings | F14: =C6 -> 47
B15: ✅ Closed Findings | C15: =COUNTIF(AUDITS!J:J, "closed") -> 16 | E15: ✅ Closed Findings | F15: =COUNTIFS(NMI!M4:M4953, "Closed") -> 47
B16: ⏳ Open Findings | C16: =COUNTIF(AUDITS!J:J, "Open") -> 12 | E16: ⏳ Open Findings | F16: =COUNTIFS(NMI!M6:M4953, "Open") -> 30
B17: 🚨 Overdue Findings | C17: =COUNTIFS(AUDITS!J4:J5000, "<>Closed", AUDITS!K4:K5000, "<" & TODAY(), AUDITS!K4:K5000, "<>""") -> 9 | E17: 🚨 Overdue Findings | F17: =COUNTIFS(NMI!M4:M4953,"<>Closed",NMI!L4:L4953, "<"&TODAY(),NMI!L4:L4953,"<>""") -> 32
B18: ➡ In Progress | C18: =COUNTIF(AUDITS!J:J, "In Progress") -> 5 | E18: ➡ In Progress | F18: =COUNTIFS(NMI!M4:M4953, "In Progress") -> 4
B20: BY Month | E20: By Month
B21: Month | C21: Findings | E21: Month | F21: Findings
B22: Mar | C22: =COUNTIF(AUDITS!O4:O5000, B22) -> 5 | E22: Jun | F22: =COUNTIF(NMI!N3:N4953,E22) -> 25
B23: Apr | C23: =COUNTIF(AUDITS!O4:O5000, B23) -> 12 | E23: Jul | F23: =COUNTIF(NMI!N4:N4954,E23) -> 39
B24: May | C24: =COUNTIF(AUDITS!O4:O5000, B24) -> 15
B25: Jun | C25: =COUNTIF(AUDITS!O4:O5000, B25) -> 1
B26: Jul | C26: =COUNTIF(AUDITS!O5:O5001, B26) -> 0

Sheet Progress Report
C2: HSSE MONTHLY REPORT
F4: Acronyms
A5: DATE: | E5: CAAK | F5: Civil Aviation Authority Kiribati
A6: By | B6: HSSEF | E6: HSSE | F6: Health Safety Security Environment
A7: Report for | E7: SSCWB | F7: SSC Walk About
E8: NMR | F8: Near Miss Reporting
E9: IR | F9: Incident Reporting
E10: LOD3 E.Insp | F10: Line of Defense Inspection - Electrical
A12: Progress Summary Table
A14: Source | B14: No. Reports | C14: Open | D14: In Progress | E14: Close | F14: Overdue | G14: Remarks
A15: CAAK | B15: =COUNTIF(AUDITS!C4:C5008, "CAAK") -> 2 | C15: =COUNTIFS(AUDITS!C:C, "CAAK",AUDITS!J:J, Open) -> 1 | D15: =COUNTIFS(AUDITS!C:C, "CAAK",AUDITS!J:J, In_Progress) -> 0
A16: HSSE | B16: =COUNTIF(AUDITS!C4:C5000, "HSSE") -> 14
A17: SSCWB | B17: =COUNTIF(AUDITS!C4:C5008, "SSC WB") -> 12
A18: NMR | B18: =COUNTIF(NMI!H4:H4961, "Nearmiss") -> 47
A19: IR | B19: =COUNTIF(NMI!G12:G4961, "Incident")+COUNTA(IR!A2:A5000) -> 10
A20: LOD3 E.Insp | B20: =COUNTIF(AUDITS!C4:C5008, "LOD3 E.Insp") -> 5

Sheet Report Award Reports
G1: NMA | H1: 2-25
C4: Employee Near Miss Reporting | S4: Month | T4: Dates
D5: Statistics for : | E5: July | P5: For the month | Q5: =IF(E5="","",VLOOKUP(E5,Months,2,0)) -> 45839 | S5: January | T5: 45658
B6: Date: | C6: =TODAY() -> 45985
B7: This report summarizes the Near Miss participation for the specified period. Below is the list of staff members and the number of Near Miss reports they have submitted. | P7: End of Month (Auto) | Q7: =IF(Q5="","",EOMONTH(Q5, 0)) -> 45869 | S7: February | T7: 45689
C12: Staff & No. of Nearmiss reported | S12: March | T12: 45717
C14: =IF(D14="","",ROW(C1)) -> 1 | D14: {=_xlfn._xlws.FILTER( _xlfn.UNIQUE( _xlfn._xlws.FILTER( NMI!D2:D953, (NMI!H2:H953="Nearmiss") * (NMI!B2:B953>=$Q$5) * (NMI!B2:B953<=$Q$7) ) ), ( COUNTIFS( NMI!D:D, _xlfn.UNIQUE( _xlfn._xlws.FILTER( NMI!D2:D953, (NMI!H2:H953="Nearmiss") * (NMI!B2:B953>=$Q$5) * (NMI!B2:B953<=$Q$7) ) ), NMI!H:H, "Nearmiss", NMI!B:B, ">=" & $Q$5, NMI!B:B, "<=" & $Q$7 ) > 0 ) )} -> Baremau | E14: =IF(D14="","",COUNTIFS(NMI!D:D, D14,NMI!H:H, "Nearmiss", NMI!B:B, ">=" & $Q$5, NMI!B:B, "<=" & $Q$7)) -> 5 | S14: April | T14: 45748
C15: =IF(D15="","",ROW(C2)) -> 2 | D15: Bwabwaku | E15: =IF(D15="","",COUNTIFS(NMI!D:D, D15,NMI!H:H, "Nearmiss", NMI!B:B, ">=" & $Q$5, NMI!B:B, "<=" & $Q$7)) -> 2 | S15: May | T15: 45778
C16: =IF(D16="","",ROW(C3)) -> 3 | D16: Kakianako | E16: =IF(D16="","",COUNTIFS(NMI!D:D, D16,NMI!H:H, "Nearmiss", NMI!B:B, ">=" & $Q$5, NMI!B:B, "<=" & $Q$7)) -> 1 | S16: June | T16: 45809
C17: =IF(D17="","",ROW(C4)) -> 4 | D17: Kimwaere | E17: =IF(D17="","",COUNTIFS(NMI!D:D, D17,NMI!H:H, "Nearmiss", NMI!B:B, ">=" & $Q$5, NMI!B:B, "<=" & $Q$7)) -> 2 | S17: July | T17: 45839
C18: =IF(D18="","",ROW(C5)) -> 5 | D18: Teibouri | E18: =IF(D18="","",COUNTIFS(NMI!D:D, D18,NMI!H:H, "Nearmiss", NMI!B:B, ">=" & $Q$5, NMI!B:B, "<=" & $Q$7)) -> 2 | S18: August | T18: 45870
C19: =IF(D19="","",ROW(C6)) -> 6 | D19: Tekaaibuti | E19: =IF(D19="","",COUNTIFS(NMI!D:D, D19,NMI!H:H, "Nearmiss", NMI!B:B, ">=" & $Q$5, NMI!B:B, "<=" & $Q$7)) -> 1 | S19: September | T19: 45901
C20: =IF(D20="","",ROW(C7)) -> 7 | D20: Tiare | E20: =IF(D20="","",COUNTIFS(NMI!D:D, D20,NMI!H:H, "Nearmiss", NMI!B:B, ">=" & $Q$5, NMI!B:B, "<=" & $Q$7)) -> 2 | S20: October | T20: 45931
C21: =IF(D21="","",ROW(C8)) -> 8 | D21: Tiiroa | E21: =IF(D21="","",COUNTIFS(NMI!D:D, D21,NMI!H:H, "Nearmiss", NMI!B:B, ">=" & $Q$5, NMI!B:B, "<=" & $Q$7)) -> 2 | S21: November | T21: 45962
C22: =IF(D22="","",ROW(C9)) -> 9 | D22: Tukuaho | E22: =IF(D22="","",COUNTIFS(NMI!D:D, D22,NMI!H:H, "Nearmiss", NMI!B:B, ">=" & $Q$5, NMI!B:B, "<=" & $Q$7)) -> 1 | S22: December | T22: 45992
C23: =IF(D23="","",ROW(C10)) -> 10 | D23: William | E23: =IF(D23="","",COUNTIFS(NMI!D:D, D23,NMI!H:H, "Nearmiss", NMI!B:B, ">=" & $Q$5, NMI!B:B, "<=" & $Q$7)) -> 1
C24: =IF(D24="","",ROW(C11)) -> 11 | D24: Aratite | E24: =IF(D24="","",COUNTIFS(NMI!D:D, D24,NMI!H:H, "Nearmiss", NMI!B:B, ">=" & $Q$5, NMI!B:B, "<=" & $Q$7)) -> 2
C25: =IF(D25="","",ROW(C12)) | E25: =IF(D25="","",COUNTIFS(NMI!D:D, D25,NMI!H:H, "Nearmiss", NMI!B:B, ">=" & $Q$5, NMI!B:B, "<=" & $Q$7))
C26: =IF(D26="","",ROW(C13)) | E26: =IF(D26="","",COUNTIFS(NMI!D:D, D26,NMI!H:H, "Nearmiss", NMI!B:B, ">=" & $Q$5, NMI!B:B, "<=" & $Q$7))
C27: =IF(D27="","",ROW(C14)) | E27: =IF(D27="","",COUNTIFS(NMI!D:D, D27,NMI!H:H, "Nearmiss", NMI!B:B, ">=" & $Q$5, NMI!B:B, "<=" & $Q$7))
C28: =IF(D28="","",ROW(C15)) | E28: =IF(D28="","",COUNTIFS(NMI!D:D, D28,NMI!H:H, "Nearmiss", NMI!B:B, ">=" & $Q$5, NMI!B:B, "<=" & $Q$7))
C29: =IF(D29="","",ROW(C16)) | E29: =IF(D29="","",COUNTIFS(NMI!D:D, D29,NMI!H:H, "Nearmiss", NMI!B:B, ">=" & $Q$5, NMI!B:B, "<=" & $Q$7))
C30: =IF(D30="","",ROW(C17)) | E30: =IF(D30="","",COUNTIFS(NMI!D:D, D30,NMI!H:H, "Nearmiss", NMI!B:B, ">=" & $Q$5, NMI!B:B, "<=" & $Q$7))
C31: =IF(D31="","",ROW(C18)) | E31: =IF(D31="","",COUNTIFS(NMI!D:D, D31,NMI!H:H, "Nearmiss", NMI!B:B, ">=" & $Q$5, NMI!B:B, "<=" & $Q$7))
C32: =IF(D32="","",ROW(C19)) | E32: =IF(D32="","",COUNTIFS(NMI!D:D, D32,NMI!H:H, "Nearmiss", NMI!B:B, ">=" & $Q$5, NMI!B:B, "<=" & $Q$7))
C33: =IF(D33="","",ROW(C20)) | E33: =IF(D33="","",COUNTIFS(NMI!D:D, D33,NMI!H:H, "Nearmiss", NMI!B:B, ">=" & $Q$5, NMI!B:B, "<=" & $Q$7))
C34: =IF(D34="","",ROW(C21)) | E34: =IF(D34="","",COUNTIFS(NMI!D:D, D34,NMI!H:H, "Nearmiss", NMI!B:B, ">=" & $Q$5, NMI!B:B, "<=" & $Q$7))
C35: =IF(D35="","",ROW(C22)) | E35: =IF(D35="","",COUNTIFS(NMI!D:D, D35,NMI!H:H, "Nearmiss", NMI!B:B, ">=" & $Q$5, NMI!B:B, "<=" & $Q$7))

Sheet AUDITS
F1: HSSE Findings Register
A3: Item# | B3: Audit Date | C3: Source | D3: LOCID | E3: Location ID | F3: Findings | G3: Risk | H3: Recommendation | I3: Responsible Officer | J3: Status | K3: Target Date | L3: % complete | M3: Actual Date | N3: Serverity | O3: Month
A4: =IF((Table1[[#This Row],[Audit Date]]=""),"",ROW(A1)) -> 1 | B4: 45793 | C4: CAAK | D4: 17 | E4: Bon | F4: Calibration of Testing equipments | G4: Undetected contaminations | H4: Invite calibration party to conduct calibration | I4: Admin | J4: Closed | K4: 45868 | L4: 0.25 | N4: High | O4: =TEXT(Table1[[#This Row],[Audit Date]],"mmm") -> May
A5: =IF((Table1[[#This Row],[Audit Date]]=""),"",ROW(A2)) -> 2 | B5: 45793 | C5: CAAK | D5: 0 | E5: BET | F5: Training for refreshers have not been conducted | G5: Not comply to aviation | H5: ADS recruitment in order to run ACE refresher training | I5: Management | J5: Open | K5: TBC | N5: High | O5: =TEXT(Table1[[#This Row],[Audit Date]],"mmm") -> May
A6: =IF((Table1[[#This Row],[Audit Date]]=""),"",ROW(A3)) -> 3 | B6: 45792 | C6: HSSE | D6: 0 | E6: BET | F6: entering restricted area without complete ppe | G6: Injury/rules violation | H6: Train and awareness of NMI and Safe practice To inform those who are referred in this spot | I6: HSSE | J6: Closed | K6: 45807 | L6: 1 | N6: Low | O6: =TEXT(Table1[[#This Row],[Audit Date]],"mmm") -> May
A7: =IF((Table1[[#This Row],[Audit Date]]=""),"",ROW(A4)) -> 4 | B7: 45806 | C7: HSSE | D7: 11 | E7: NTTFS | F7: Calibration required for Meters ULP meter off 50L less ADO meter off by 30L less | G7: Stock issue | H7: Calibration needed to ensure precision | I7: Operation | J7: Open | K7: 45863 | N7: Low | O7: =TEXT(Table1[[#This Row],[Audit Date]],"mmm") -> May
A8: =IF((Table1[[#This Row],[Audit Date]]=""),"",ROW(A5)) -> 5 | B8: 45806 | C8: HSSE | D8: 0.1 | E8: NTTFS | F8: Filter change for meter strainers | G8: Dirty fuel/meter damage | H8: Fitters to maintain filter and strainer inspection | I8: Fitters | J8: Open | K8: 45869 | L8: 0 | N8: Medium | O8: =TEXT(Table1[[#This Row],[Audit Date]],"mmm") -> May
A9: =IF((Table1[[#This Row],[Audit Date]]=""),"",ROW(A6)) -> 6 | B9: 45818 | C9: HSSE | D9: 15 | E9: Admin and Operation office | F9: Office Building Integrity is quite old and risky | G9: Fatal, Building Collapse | H9: To invite a structural engineer on the building assessment | I9: Management | J9: Open | K9: 45869 | N9: High | O9: =TEXT(Table1[[#This Row],[Audit Date]],"mmm") -> Jun
A10: =IF((Table1[[#This Row],[Audit Date]]=""),"",ROW(A7)) -> 7 | B10: 45770 | C10: HSSE | D10: 9 | E10: Firepump | F10: Team performing hot works without F.E onsite | G10: Fire Hazard | H10: Ensure works is conducted in accordance with work permit | I10: Team Leader | J10: Closed | K10: 45770 | L10: 1 | M10: 45770 | N10: High | O10: =TEXT(Table1[[#This Row],[Audit Date]],"mmm") -> Apr
A11: =IF((Table1[[#This Row],[Audit Date]]=""),"",ROW(A8)) -> 8 | B11: 45806 | C11: HSSE | D11: 13 | E11: BET | F11: Holes and posts of the fence damaged | G11: unauthorize access | H11: To construct a concrete-type fence with a security fence | I11: Maintenance/Contractor | J11: In progress | K11: 45899 | L11: 0.4 | N11: High | O11: =TEXT(Table1[[#This Row],[Audit Date]],"mmm") -> May
A12: =IF((Table1[[#This Row],[Audit Date]]=""),"",ROW(A9)) -> 9 | B12: 45792 | C12: HSSE | D12: 0 | E12: BET | F12: documentation of aviation release was not completed | G12: Not comply to aviation | H12: To sign off the release note and to remove copy for filing | I12: OS | J12: Open | K12: 45901 | L12: 0.4 | N12: Medium | O12: =TEXT(Table1[[#This Row],[Audit Date]],"mmm") -> May
A13: =IF((Table1[[#This Row],[Audit Date]]=""),"",ROW(A10)) -> 10 | B13: 45806 | C13: HSSE | D13: 11 | E13: NTTFS | F13: More than 3 drums are stored at the NTTFS | G13: contamination/STF | H13: 3 drums is the safety requirements for transferring 3 products | I13: Operation | J13: Closed | K13: 45823 | L13: 1 | N13: Low | O13: =TEXT(Table1[[#This Row],[Audit Date]],"mmm") -> May
A14: =IF((Table1[[#This Row],[Audit Date]]=""),"",ROW(A11)) -> 11 | B14: 45806 | C14: HSSE | D14: 11 | E14: NTTFS | F14: Poor House Keeping | G14: STF | H14: Need to improve house keeping | I14: Operation | J14: Closed | K14: 45835 | N14: Medium | O14: =TEXT(Table1[[#This Row],[Audit Date]],"mmm") -> May
A15: =IF((Table1[[#This Row],[Audit Date]]=""),"",ROW(A12)) -> 12 | B15: 45806 | C15: HSSE | D15: 11 | E15: NTTFS | F15: Pipe and shed heavily corroded | G15: falling object/collapse structure | H15: Repairing needed for this | I15: Operation | J15: In progress | K15: 45901 | L15: 0.9 | N15: High | O15: =TEXT(Table1[[#This Row],[Audit Date]],"mmm") -> May
A16: =IF((Table1[[#This Row],[Audit Date]]=""),"",ROW(A13)) -> 13 | B16: 45793 | C16: HSSE | D16: 0 | E16: BET | F16: No gas detector available for hot work purpose | G16: Fire Hazard | H16: To have gas detector in place | I16: operation | J16: Closed | K16: TBC | N16: Medium | O16: =TEXT(Table1[[#This Row],[Audit Date]],"mmm") -> May
A17: =IF((Table1[[#This Row],[Audit Date]]=""),"",ROW(A14)) -> 14 | B17: 45806 | C17: HSSE | D17: 11 | E17: NTTFS | F17: Static Clip for TTFS is not properly connected | G17: explostion | H17: Fixing the static cable is recommended asap | I17: Operation | J17: Open | K17: TBC | N17: High | O17: =TEXT(Table1[[#This Row],[Audit Date]],"mmm") -> May
A18: =IF((Table1[[#This Row],[Audit Date]]=""),"",ROW(A15)) -> 15 | B18: 45806 | C18: HSSE | D18: 12 | E18: NTF | F18: Tanks need painting on Valves Pressure Relief lines Stairs Roof Rails Roof Manholes Tank 10 Varec Meter not working | G18: Leakage | H18: Repair and Maintenance works is needed in order to keep the tanks conditions | I18: Operation | J18: Open | K18: TBC | N18: High | O18: =TEXT(Table1[[#This Row],[Audit Date]],"mmm") -> May
A19: =IF((Table1[[#This Row],[Audit Date]]=""),"",ROW(A16)) -> 16 | B19: 45806 | C19: HSSE | D19: 13 | E19: NTF Yard | F19: Metals & Scraps are stacked in the backyard, blocking the NTF back gate | G19: Limit access of emergency entries etc | H19: Removing or selling out the scraps for public use if needed | I19: Operation | J19: Closed | K19: TBC | N19: Low | O19: =TEXT(Table1[[#This Row],[Audit Date]],"mmm") -> May
A20: =IF((Table1[[#This Row],[Audit Date]]=""),"",ROW(A17)) -> 17 | B20: 45731 | C20: LOD3 E.Insp | D20: 0 | E20: KOIL Office | F20: Single-phase system, 30A reading | G20: Electrical Hazards | H20: Okay | I20: None | J20: Closed | K20: TBC | N20: High | O20: =TEXT(Table1[[#This Row],[Audit Date]],"mmm") -> Mar
A21: =IF((Table1[[#This Row],[Audit Date]]=""),"",ROW(A18)) -> 18 | B21: 45731 | C21: LOD3 E.Insp | D21: 15 | E21: Admin and Operation office | F21: Betio office require new seals or conduits Signs of aging and non-compliant installations were observed | G21: Electrical Hazards | H21: Install new seals and conduits where needed Upgrade wiring to meet current electrical safety standards | I21: Maintenance/Contractor | J21: Open | K21: TBC | N21: High | O21: =TEXT(Table1[[#This Row],[Audit Date]],"mmm") -> Mar
A22: =IF((Table1[[#This Row],[Audit Date]]=""),"",ROW(A19)) -> 19 | B22: 45731 | C22: LOD3 E.Insp | D22: 1,15 | E22: Operation & Admin Office | F22: Red phase: 57A Yellow phase: 66A Blue phase: 49A | G22: Electrical Hazards | H22: Okay | I22: None | J22: Closed | K22: TBC | N22: High | O22: =TEXT(Table1[[#This Row],[Audit Date]],"mmm") -> Mar
A23: =IF((Table1[[#This Row],[Audit Date]]=""),"",ROW(A20)) -> 20 | B23: 45731 | C23: LOD3 E.Insp | D23: 2,17 | E23: 1. Main Switch Board (Backup Gen. Area) 2. Operation office main switch board 3. Bonriki Main Switch Board | F23: Both Betio and Bonriki offices have uncovered electrical switchboards Live wires exposed in the main distribution box — poses significant electric shock and fire hazards. | G23: Electrical Hazards | H23: Replace or properly cover the distribution boxes and switchboards at both sites. Immediate renewal and rectification are strongly advised to ensure safety compliance. | I23: Maintenance/Contractor | J23: Open | K23: TBC | N23: High | O23: =TEXT(Table1[[#This Row],[Audit Date]],"mmm") -> Mar
A24: =IF((Table1[[#This Row],[Audit Date]]=""),"",ROW(A21)) -> 21 | B24: 45731 | C24: LOD3 E.Insp | D24: 6,7 | E24: Old Tank Farm (Tk2,3,4) | F24: -Most buildings, machines, pumps, and fuel tanks have no earth wiring. - Some grounding connections were found to be disconnected. | G24: Electrical Hazards | H24: Install or reconnect earth wires on all applicable equipment and structures. Conduct a full grounding test after corrections are made. | I24: Maintenance | J24: Open | K24: TBC | N24: High | O24: =TEXT(Table1[[#This Row],[Audit Date]],"mmm") -> Mar
A25: =IF((Table1[[#This Row],[Audit Date]]=""),"",ROW(A22)) -> 22 | B25: 45770 | C25: SSC WB | D25: 0 | E25: BET | F25: To conduct drills without water | G25: Lack competency | H25: To carry out Monthly Drills | I25: Operation & HSSE | J25: Closed | K25: 45814 | L25: 1 | N25: High | O25: =TEXT(Table1[[#This Row],[Audit Date]],"mmm") -> Apr
A26: =IF((Table1[[#This Row],[Audit Date]]=""),"",ROW(A23)) -> 23 | B26: 45770 | C26: SSC WB | D26: 14 | E26: BET | F26: Waste Oil Purification | G26: Pile up of waste oils | H26: Following up on the recoiling of machine in order to have this moved forward | I26: HSSE | J26: In progress | K26: 45808 | L26: 0.8 | N26: Medium | O26: =TEXT(Table1[[#This Row],[Audit Date]],"mmm") -> Apr
A27: =IF((Table1[[#This Row],[Audit Date]]=""),"",ROW(A24)) -> 24 | B27: 45770 | C27: SSC WB | D27: 0 | E27: BET | F27: Assembly area signs | G27: Injury/Panic | H27: Need to put Assembly area signs at the assembly area | I27: HSSE | J27: In progress | K27: 45840 | L27: 0.9 | N27: Medium | O27: =TEXT(Table1[[#This Row],[Audit Date]],"mmm") -> Apr | P27: Temporary Closed by by patching them with cables and obstructions
A28: =IF((Table1[[#This Row],[Audit Date]]=""),"",ROW(A25)) -> 25 | B28: 45770 | C28: SSC WB | D28: 0.1 | E28: BET | F28: Lighting to be installed on required sites | G28: Lack Visibility | H28: To install lights at the designated spots, such as Canteen, Pathway along canteen at Security Fences | I28: Admin | J28: In progress | K28: 45848 | L28: 0 | N28: High | O28: =TEXT(Table1[[#This Row],[Audit Date]],"mmm") -> Apr
A29: =IF((Table1[[#This Row],[Audit Date]]=""),"",ROW(A26)) -> 26 | B29: 45770 | C29: SSC WB | D29: 0.1 | E29: BET | F29: Fire Extinguishers are missing at certain stations | G29: Fire Hazard | H29: Replace fire extinguishers and to ensure pressure are still within acceptable readings | I29: HSSE | J29: Closed | K29: 45777 | L29: 1 | M29: 45787 | N29: High | O29: =TEXT(Table1[[#This Row],[Audit Date]],"mmm") -> Apr
A30: =IF((Table1[[#This Row],[Audit Date]]=""),"",ROW(A27)) -> 27 | B30: 45770 | C30: SSC WB | D30: 7 | E30: BET | F30: Cleaning around the compound and improve housekeeping | G30: STF and Fire | H30: Compound cleaning, and ensure housekeeping is mandated | I30: Operation | J30: Closed | K30: 45777 | L30: 1 | M30: 45818 | N30: Medium | O30: =TEXT(Table1[[#This Row],[Audit Date]],"mmm") -> Apr
A31: =IF((Table1[[#This Row],[Audit Date]]=""),"",ROW(A28)) -> 28 | B31: 45770 | C31: SSC WB | D31: 9 | E31: BET | F31: Fire Pump Issues | G31: Fire Hazard | H31: Ensure the Fire Pump is workable and is to be tested. | I31: Operation | J31: Closed | K31: TBC | M31: 45838 | N31: High | O31: =TEXT(Table1[[#This Row],[Audit Date]],"mmm") -> Apr
A32: =IF((Table1[[#This Row],[Audit Date]]=""),"",ROW(A29)) -> 29 | B32: 45770 | C32: SSC WB | D32: 0 | E32: BET | F32: Camera Survailance at required site | G32: Safety & Security Issues | H32: To install camera at blindspots such as Canteen, Firepump area, Gate at cashier | I32: IT | J32: Closed | K32: TBC | L32: 0.5 | N32: Medium | O32: =TEXT(Table1[[#This Row],[Audit Date]],"mmm") -> Apr
A33: =IF((Table1[[#This Row],[Audit Date]]=""),"",ROW(A30)) -> 30 | B33: 45770 | C33: SSC WB | D33: 11 | E33: NTTFS | F33: Safety Signage are detached from the fence | G33: Lack Safety Awareness | H33: Reattached signs to be visible by staff, customers & visitors | I33: HSSE | J33: Closed | K33: 45777 | L33: 1 | M33: 45791 | N33: Medium | O33: =TEXT(Table1[[#This Row],[Audit Date]],"mmm") -> Apr
A34: =IF((Table1[[#This Row],[Audit Date]]=""),"",ROW(A31)) -> 31 | B34: 45770 | C34: SSC WB | D34: 9 | E34: Foam System | F34: Incomplete Foam system | G34: Unable to stop tank on fire | H34: Completing the foam system will be required for effective fire emergency response. | I34: Management | J34: Open | K34: TBC | N34: High | O34: =TEXT(Table1[[#This Row],[Audit Date]],"mmm") -> Apr
A35: =IF((Table1[[#This Row],[Audit Date]]=""),"",ROW(A32)) -> 32 | B35: 45800 | C35: SSC WB | D35: 11 | E35: BET | F35: NDFS required to be build to comply to MELAD standards | G35: Ground spills | H35: Constructing a bunded wall with a drainage or a New DFS project construction | I35: Operation | J35: Open | K35: TBC | N35: Medium | O35: =TEXT(Table1[[#This Row],[Audit Date]],"mmm") -> May
A36: =IF((Table1[[#This Row],[Audit Date]]=""),"",ROW(A33)) -> 33 | B36: 45770 | C36: SSC WB | D36: 2,14 | E36: BET | F36: Vegetation and Trees (teango) grown up and triggering fire hazards to the fuel farm | G36: Fire Hazard | H36: to clear all vegetation that is likely to contribute to fire hazards | I36: Operation | J36: Closed | K36: 45848 | L36: 0.8 | N36: Medium | O36: =TEXT(Table1[[#This Row],[Audit Date]],"mmm") -> Apr
A37: =IF((Table1[[#This Row],[Audit Date]]=""),"",ROW(A34)) | O37: =TEXT(Table1[[#This Row],[Audit Date]],"mmm") -> Jan

Sheet NMI
A3: NM/I no. | B3: Date | C3: Time | D3: Reported by | E3: Loc ID | F3: Location | G3: Issue | H3: Types of Reporting | I3: Action Taken | J3: Recommendation | K3: Responsible Staff | L3: Target Date | M3: Status | N3: RD | O3: TD
A4: =IF((Table1333[[#This Row],[Date]]=""),"",ROW(A1)) -> 1 | B4: 45836 | C4: 0.41666667 | D4: Angintetaake | E4: 13 | F4: =IF(Table1333[[#This Row],[Loc ID]]="","",VLOOKUP(Table1333[[#This Row],[Loc ID]],Loc_ID[],2,0)) -> NTF Fences | G4: A person enters KOIL Depot and walk out on the other side | H4: Nearmiss | I4: Report as NearMiss | J4: Temporary close the holes prior the new fence project roll out | K4: Maintenance | L4: 45842 | M4: Closed | N4: =IF(Table1333[[#This Row],[Date]]="","",(TEXT(Table1333[[#This Row],[Date]],"MMM"))) -> Jun | O4: =IF(Table1333[[#This Row],[Target Date]]="","",(TEXT(Table1333[[#This Row],[Target Date]],"MMM"))) -> Jul
A5: =IF((Table1333[[#This Row],[Date]]=""),"",ROW(A2)) -> 2 | B5: 45810 | C5: 0.43055556 | D5: Aratite | E5: 1 | F5: =IF(Table1333[[#This Row],[Loc ID]]="","",VLOOKUP(Table1333[[#This Row],[Loc ID]],Loc_ID[],2,0)) -> Operation Office Area | G5: Entry safety signs' visibility and readability are low | H5: Nearmiss | I5: Report as NearMiss | J5: Design a new sign for safety communication | K5: HSSEF | L5: 45825 | M5: In progress | N5: =IF(Table1333[[#This Row],[Date]]="","",(TEXT(Table1333[[#This Row],[Date]],"MMM"))) -> Jun | O5: =IF(Table1333[[#This Row],[Target Date]]="","",(TEXT(Table1333[[#This Row],[Target Date]],"MMM"))) -> Jun
A6: =IF((Table1333[[#This Row],[Date]]=""),"",ROW(A3)) -> 3 | B6: 45810 | C6: 0.4375 | D6: Aratite | E6: 0.3 | F6: =IF(Table1333[[#This Row],[Loc ID]]="","",VLOOKUP(Table1333[[#This Row],[Loc ID]],Loc_ID[],2,0)) -> Delivery Vehicles | G6: Tanker Truck 4378 exhaust usually emit into the driver cabin | H6: Nearmiss | I6: Report as NearMiss | J6: Raise the Exhaust above te driver cabin | K6: OM | L6: 45832 | M6: Open | N6: =IF(Table1333[[#This Row],[Date]]="","",(TEXT(Table1333[[#This Row],[Date]],"MMM"))) -> Jun | O6: =IF(Table1333[[#This Row],[Target Date]]="","",(TEXT(Table1333[[#This Row],[Target Date]],"MMM"))) -> Jun
A7: =IF((Table1333[[#This Row],[Date]]=""),"",ROW(A4)) -> 4 | B7: 45837 | C7: 0.42361111 | D7: Baremau | E7: 11 | F7: =IF(Table1333[[#This Row],[Loc ID]]="","",VLOOKUP(Table1333[[#This Row],[Loc ID]],Loc_ID[],2,0)) -> TTFS and Drums Area | G7: JetA1 Deadman Switch at TTFS is not working | H7: Nearmiss | I7: Report as NearMiss | J7: Repair and Maintenance is required | K7: Fitters | L7: 45869 | M7: Closed | N7: =IF(Table1333[[#This Row],[Date]]="","",(TEXT(Table1333[[#This Row],[Date]],"MMM"))) -> Jun | O7: =IF(Table1333[[#This Row],[Target Date]]="","",(TEXT(Table1333[[#This Row],[Target Date]],"MMM"))) -> Jul
A8: =IF((Table1333[[#This Row],[Date]]=""),"",ROW(A5)) -> 5 | B8: 45842 | C8: 0.42361111 | D8: Baremau | E8: 0.3 | F8: =IF(Table1333[[#This Row],[Loc ID]]="","",VLOOKUP(Table1333[[#This Row],[Loc ID]],Loc_ID[],2,0)) -> Delivery Vehicles | G8: JetA1 Drum Filling needs a downpipe to avoid splash filling | H8: Nearmiss | I8: Report as NearMiss | J8: fabricating and installation of nozzle extension following soak test procedures as per SAOM | K8: Fitters | L8: 45869 | M8: Open | N8: =IF(Table1333[[#This Row],[Date]]="","",(TEXT(Table1333[[#This Row],[Date]],"MMM"))) -> Jul | O8: =IF(Table1333[[#This Row],[Target Date]]="","",(TEXT(Table1333[[#This Row],[Target Date]],"MMM"))) -> Jul
A9: =IF((Table1333[[#This Row],[Date]]=""),"",ROW(A6)) -> 6 | B9: 45847 | C9: 0.40625 | D9: Baremau | E9: 0.5 | F9: =IF(Table1333[[#This Row],[Loc ID]]="","",VLOOKUP(Table1333[[#This Row],[Loc ID]],Loc_ID[],2,0)) -> Procedures | G9: Staff forgetting procedures at their operation station. | H9: Nearmiss | I9: Report as NearMiss | J9: Procedures to be displayed at sites | K9: OM | L9: 45869 | M9: Open | N9: =IF(Table1333[[#This Row],[Date]]="","",(TEXT(Table1333[[#This Row],[Date]],"MMM"))) -> Jul | O9: =IF(Table1333[[#This Row],[Target Date]]="","",(TEXT(Table1333[[#This Row],[Target Date]],"MMM"))) -> Jul | Q9: 45831
A10: =IF((Table1333[[#This Row],[Date]]=""),"",ROW(A7)) -> 7 | B10: 45847 | C10: 0.375 | D10: Baremau | E10: 0.4 | F10: =IF(Table1333[[#This Row],[Loc ID]]="","",VLOOKUP(Table1333[[#This Row],[Loc ID]],Loc_ID[],2,0)) -> Compliance | G10: Staff carry prohibited items inside the restricted area. | H10: Nearmiss | I10: Report Verbal and Writing | J10: Inform staff of the safety rules inside the terminal To spot check staff on their compliance inside the terminal | K10: OS/HSSEF | L10: 45863 | M10: Closed | N10: =IF(Table1333[[#This Row],[Date]]="","",(TEXT(Table1333[[#This Row],[Date]],"MMM"))) -> Jul | O10: =IF(Table1333[[#This Row],[Target Date]]="","",(TEXT(Table1333[[#This Row],[Target Date]],"MMM"))) -> Jul
A11: =IF((Table1333[[#This Row],[Date]]=""),"",ROW(A8)) -> 8 | B11: 45847 | C11: 0.40972222 | D11: Baremau | E11: 0.4 | F11: =IF(Table1333[[#This Row],[Loc ID]]="","",VLOOKUP(Table1333[[#This Row],[Loc ID]],Loc_ID[],2,0)) -> Compliance | G11: Static cable is too shorts especially tanker trucks. Cannot fully bond connection to gas station tanks as the cable is not long enough to reach those tanks | H11: Nearmiss | I11: Report as NearMiss | J11: Extending the Static cables in order to reach the end tank bonding | K11: Fitters | L11: 45898 | M11: Open | N11: =IF(Table1333[[#This Row],[Date]]="","",(TEXT(Table1333[[#This Row],[Date]],"MMM"))) -> Jul | O11: =IF(Table1333[[#This Row],[Target Date]]="","",(TEXT(Table1333[[#This Row],[Target Date]],"MMM"))) -> Aug
A12: =IF((Table1333[[#This Row],[Date]]=""),"",ROW(A9)) -> 9 | B12: 45845 | C12: 0.41666667 | D12: Bwabwaku | E12: 0.4 | F12: =IF(Table1333[[#This Row],[Loc ID]]="","",VLOOKUP(Table1333[[#This Row],[Loc ID]],Loc_ID[],2,0)) -> Compliance | G12: Staff vehicle have been parked in front of office for over a month. | H12: Nearmiss | I12: Report to OM and OS | J12: Inform him to get his car out of sight as it creates blockade to access | K12: OS | L12: 45869 | M12: Closed | N12: =IF(Table1333[[#This Row],[Date]]="","",(TEXT(Table1333[[#This Row],[Date]],"MMM"))) -> Jul | O12: =IF(Table1333[[#This Row],[Target Date]]="","",(TEXT(Table1333[[#This Row],[Target Date]],"MMM"))) -> Jul
A13: =IF((Table1333[[#This Row],[Date]]=""),"",ROW(A10)) -> 10 | B13: 45845 | C13: 0.41666667 | D13: Bwabwaku | E13: 3 | F13: =IF(Table1333[[#This Row],[Loc ID]]="","",VLOOKUP(Table1333[[#This Row],[Loc ID]],Loc_ID[],2,0)) -> DFS,TTFS area | G13: Mudpool infront of DFS usually flooded and sometimes the flows over to the garage when a tanker truck runs through the pool | H13: Nearmiss | I13: Remove excess water from the garage | J13: This is required to be leveled to addressed this issues | K13: Maintenance | L13: 45872 | M13: Open | N13: =IF(Table1333[[#This Row],[Date]]="","",(TEXT(Table1333[[#This Row],[Date]],"MMM"))) -> Jul | O13: =IF(Table1333[[#This Row],[Target Date]]="","",(TEXT(Table1333[[#This Row],[Target Date]],"MMM"))) -> Aug
A14: =IF((Table1333[[#This Row],[Date]]=""),"",ROW(A11)) -> 11 | B14: 45827 | C14: 0.41666667 | D14: Ioane (OIA) | E14: 0 | F14: =IF(Table1333[[#This Row],[Loc ID]]="","",VLOOKUP(Table1333[[#This Row],[Loc ID]],Loc_ID[],2,0)) -> Others | G14: Grown up trees next to fuel farm in Arorae, Fire Risk: Trees can serve as fuel in the event of a fire, increasing the risk of rapid spread. Structural Damage: Falling branches or entire trees (especially during storms) can damage fuel tanks or infrastructure. Root Intrusion: Tree roots can damage underground fuel lines or containment systems. Access Obstruction: Overgrown trees can block emergency access routes or visibility. | H14: Nearmiss | I14: Reported to HRM and reviewed by HSSEF | J14: Tree Removal or Trimming: Remove or significantly trim trees that pose a direct threat. Implement vegetation management plan | K14: Ioane & Contractors | L14: 45835 | M14: Closed | N14: =IF(Table1333[[#This Row],[Date]]="","",(TEXT(Table1333[[#This Row],[Date]],"MMM"))) -> Jun | O14: =IF(Table1333[[#This Row],[Target Date]]="","",(TEXT(Table1333[[#This Row],[Target Date]],"MMM"))) -> Jun
A15: =IF((Table1333[[#This Row],[Date]]=""),"",ROW(A12)) -> 12 | B15: 45843 | C15: 0.41180556 | D15: Kakianako | E15: 0.4 | F15: =IF(Table1333[[#This Row],[Loc ID]]="","",VLOOKUP(Table1333[[#This Row],[Loc ID]],Loc_ID[],2,0)) -> Compliance | G15: Staff walking without minimum PPE requirement | H15: Nearmiss | I15: Warn the staff and report | J15: consulation with those concern staff | K15: OS/HSSEF | L15: 45863 | M15: Closed | N15: =IF(Table1333[[#This Row],[Date]]="","",(TEXT(Table1333[[#This Row],[Date]],"MMM"))) -> Jul | O15: =IF(Table1333[[#This Row],[Target Date]]="","",(TEXT(Table1333[[#This Row],[Target Date]],"MMM"))) -> Jul
A16: =IF((Table1333[[#This Row],[Date]]=""),"",ROW(A13)) -> 13 | B16: 45836 | C16: 0.41666667 | D16: Kimwaere | E16: 4 | F16: =IF(Table1333[[#This Row],[Loc ID]]="","",VLOOKUP(Table1333[[#This Row],[Loc ID]],Loc_ID[],2,0)) -> WasteOil&Separator Area | G16: There are lot of waste oil drums need purification | H16: Nearmiss | I16: Report as NearMiss | J16: To follow up with Maeke on the motor coiling | K16: HSSEF | L16: 45847 | M16: Open | N16: =IF(Table1333[[#This Row],[Date]]="","",(TEXT(Table1333[[#This Row],[Date]],"MMM"))) -> Jun | O16: =IF(Table1333[[#This Row],[Target Date]]="","",(TEXT(Table1333[[#This Row],[Target Date]],"MMM"))) -> Jul
A17: =IF((Table1333[[#This Row],[Date]]=""),"",ROW(A14)) -> 14 | B17: 45836 | C17: 0.48611111 | D17: Kimwaere | E17: 13 | F17: =IF(Table1333[[#This Row],[Loc ID]]="","",VLOOKUP(Table1333[[#This Row],[Loc ID]],Loc_ID[],2,0)) -> NTF Fences | G17: An insane person enters KOIL Depot | H17: Nearmiss | I17: Report as NearMiss | J17: Temporary close the holes prior the new fence project roll out | K17: Maintenance | L17: 45842 | M17: Closed | N17: =IF(Table1333[[#This Row],[Date]]="","",(TEXT(Table1333[[#This Row],[Date]],"MMM"))) -> Jun | O17: =IF(Table1333[[#This Row],[Target Date]]="","",(TEXT(Table1333[[#This Row],[Target Date]],"MMM"))) -> Jul
A18: =IF((Table1333[[#This Row],[Date]]=""),"",ROW(A15)) -> 15 | B18: 45836 | C18: 0.42361111 | D18: Kimwaere | E18: 13 | F18: =IF(Table1333[[#This Row],[Loc ID]]="","",VLOOKUP(Table1333[[#This Row],[Loc ID]],Loc_ID[],2,0)) -> NTF Fences | G18: Need to repair fence side at KPA to Lagoon side | H18: Nearmiss | I18: Report as NearMiss | J18: fence project construction is required | K18: Contractors | L18: 45900 | M18: Open | N18: =IF(Table1333[[#This Row],[Date]]="","",(TEXT(Table1333[[#This Row],[Date]],"MMM"))) -> Jun | O18: =IF(Table1333[[#This Row],[Target Date]]="","",(TEXT(Table1333[[#This Row],[Target Date]],"MMM"))) -> Aug
A19: =IF((Table1333[[#This Row],[Date]]=""),"",ROW(A16)) -> 16 | B19: 45847 | C19: 0.45833333 | D19: Kimwaere | E19: 3 | F19: =IF(Table1333[[#This Row],[Loc ID]]="","",VLOOKUP(Table1333[[#This Row],[Loc ID]],Loc_ID[],2,0)) -> DFS,TTFS area | G19: KOIL use diesel was not covered after use which exposed to rain and other possible contaminants | H19: Nearmiss | I19: Cover up and report as Near Miss | J19: Ensuring that a KOIL use is fully covered after use | K19: Drivers/Stock | L19: 45847 | M19: Closed | N19: =IF(Table1333[[#This Row],[Date]]="","",(TEXT(Table1333[[#This Row],[Date]],"MMM"))) -> Jul | O19: =IF(Table1333[[#This Row],[Target Date]]="","",(TEXT(Table1333[[#This Row],[Target Date]],"MMM"))) -> Jul
A20: =IF((Table1333[[#This Row],[Date]]=""),"",ROW(A17)) -> 17 | B20: 45856 | C20: 0.58333333 | D20: Kimwaere | E20: 5 | F20: =IF(Table1333[[#This Row],[Loc ID]]="","",VLOOKUP(Table1333[[#This Row],[Loc ID]],Loc_ID[],2,0)) -> Lube Shed Area & Lab area | G20: Powergate truck is used until it ran out of fuel and parked beside the lab | H20: Nearmiss | I20: Tow to KOIL use and refuel the truck | J20: Driver to check on the fuel of the vehicles | K20: Drivers | L20: 45856 | M20: Closed | N20: =IF(Table1333[[#This Row],[Date]]="","",(TEXT(Table1333[[#This Row],[Date]],"MMM"))) -> Jul | O20: =IF(Table1333[[#This Row],[Target Date]]="","",(TEXT(Table1333[[#This Row],[Target Date]],"MMM"))) -> Jul
A21: =IF((Table1333[[#This Row],[Date]]=""),"",ROW(A18)) -> 18 | B21: 45836 | C21: 0.42361111 | D21: Maareke | E21: 0 | F21: =IF(Table1333[[#This Row],[Loc ID]]="","",VLOOKUP(Table1333[[#This Row],[Loc ID]],Loc_ID[],2,0)) -> Others | G21: Need for Permit to Work Training | H21: Nearmiss | I21: Report as NearMiss | J21: to propose to the board | K21: OM | L21: 45858 | M21: Open | N21: =IF(Table1333[[#This Row],[Date]]="","",(TEXT(Table1333[[#This Row],[Date]],"MMM"))) -> Jun | O21: =IF(Table1333[[#This Row],[Target Date]]="","",(TEXT(Table1333[[#This Row],[Target Date]],"MMM"))) -> Jul
... A25: =IF((Table1333[[#This Row],[Date]]=""),"",ROW(A22)) -> 22 | B25: 45827 | C25: 0.43333333 | D25: Tatang | E25: 12 | F25: =IF(Table1333[[#This Row],[Loc ID]]="","",VLOOKUP(Table1333[[#This Row],[Loc ID]],Loc_ID[],2,0)) -> NTF | G25: Electrical wiring at the Cashier office is sharing load with a single point and operating two appliances by using a powerboard | H25: Nearmiss | I25: Reported as Near Miss | J25: To separate powerport for different appliance and to avoid using powerboard | K25: OM | L25: 45841 | M25: Open | N25: =IF(Table1333[[#This Row],[Date]]="","",(TEXT(Table1333[[#This Row],[Date]],"MMM"))) -> Jun | O25: =IF(Table1333[[#This Row],[Target Date]]="","",(TEXT(Table1333[[#This Row],[Target Date]],"MMM"))) -> Jul
A26: =IF((Table1333[[#This Row],[Date]]=""),"",ROW(A23)) -> 23 | B26: 45838 | C26: 0.63541667 | D26: Tebikeiti | E26: 0.3a | F26: =IF(Table1333[[#This Row],[Loc ID]]="","",VLOOKUP(Table1333[[#This Row],[Loc ID]],Loc_ID[],2,0)) -> Vehicles & Transportation | G26: While driving vehicle 5661, I heard a loud thumping and pumping noise from one of the tyres. It made me worried because it sounded like the tyre might come off while driving. | H26: Nearmiss | I26: Slowly drive the car and report to HSSEF | J26: Marinnoora will take it for inspection from company mechanics This require service | K26: Fitters | L26: 45841 | M26: In progress | N26: =IF(Table1333[[#This Row],[Date]]="","",(TEXT(Table1333[[#This Row],[Date]],"MMM"))) -> Jun | O26: =IF(Table1333[[#This Row],[Target Date]]="","",(TEXT(Table1333[[#This Row],[Target Date]],"MMM"))) -> Jul
A27: =IF((Table1333[[#This Row],[Date]]=""),"",ROW(A24)) -> 24 | B27: 45838 | C27: 0.40486111 | D27: Teboaa (OIA) | E27: 0 | F27: =IF(Table1333[[#This Row],[Loc ID]]="","",VLOOKUP(Table1333[[#This Row],[Loc ID]],Loc_ID[],2,0)) -> Others | G27: Fence defects alongside the road in Abaiang Depot and will be vulnerable to the public if this is not addressed. | H27: Nearmiss | I27: Recorded as nearmiss and to be carried under specific safety instructions as per the work permit | J27: Fixing the fence as soon as possible | K27: Teboa & Contractors | L27: 45842 | M27: In progress | N27: =IF(Table1333[[#This Row],[Date]]="","",(TEXT(Table1333[[#This Row],[Date]],"MMM"))) -> Jun | O27: =IF(Table1333[[#This Row],[Target Date]]="","",(TEXT(Table1333[[#This Row],[Target Date]],"MMM"))) -> Jul | Q27: This is taken as a major project
A28: =IF((Table1333[[#This Row],[Date]]=""),"",ROW(A25)) -> 25 | B28: 45847 | C28: 0.41666667 | D28: Teibouri | E28: 0.4 | F28: =IF(Table1333[[#This Row],[Loc ID]]="","",VLOOKUP(Table1333[[#This Row],[Loc ID]],Loc_ID[],2,0)) -> Compliance | G28: Staff wearing worn out Safety Shoes | H28: Nearmiss | I28: Report as NearMiss | J28: Replacement of safety shoes to those who needed | K28: HSSEF | L28: 45869 | M28: Open | N28: =IF(Table1333[[#This Row],[Date]]="","",(TEXT(Table1333[[#This Row],[Date]],"MMM"))) -> Jul | O28: =IF(Table1333[[#This Row],[Target Date]]="","",(TEXT(Table1333[[#This Row],[Target Date]],"MMM"))) -> Jul
A29: =IF((Table1333[[#This Row],[Date]]=""),"",ROW(A26)) -> 26 | B29: 45858 | C29: 0.375 | D29: Teibouri | E29: 1 | F29: =IF(Table1333[[#This Row],[Loc ID]]="","",VLOOKUP(Table1333[[#This Row],[Loc ID]],Loc_ID[],2,0)) -> Operation Office Area | G29: Using of phone whilst toolbox meeting | H29: Behavior | I29: Report as NearMiss | J29: Staff to fully commit themselves to the meeting context and to able to obtain lessons. | K29: OS | L29: 45859 | M29: Closed | N29: =IF(Table1333[[#This Row],[Date]]="","",(TEXT(Table1333[[#This Row],[Date]],"MMM"))) -> Jul | O29: =IF(Table1333[[#This Row],[Target Date]]="","",(TEXT(Table1333[[#This Row],[Target Date]],"MMM"))) -> Jul
A30: =IF((Table1333[[#This Row],[Date]]=""),"",ROW(A27)) -> 27 | B30: 45839 | C30: 0.59375 | D30: Teibouri | E30: 0.4 | F30: =IF(Table1333[[#This Row],[Loc ID]]="","",VLOOKUP(Table1333[[#This Row],[Loc ID]],Loc_ID[],2,0)) -> Compliance | G30: Some staff do not fully wear PPE and not comply to Safety Rule | H30: Nearmiss | I30: Report as NearMiss | J30: Enforce & and disciplinary action required | K30: OM/OS | L30: 45848 | M30: Open | N30: =IF(Table1333[[#This Row],[Date]]="","",(TEXT(Table1333[[#This Row],[Date]],"MMM"))) -> Jul | O30: =IF(Table1333[[#This Row],[Target Date]]="","",(TEXT(Table1333[[#This Row],[Target Date]],"MMM"))) -> Jul
A31: =IF((Table1333[[#This Row],[Date]]=""),"",ROW(A28)) -> 28 | B31: 45842 | C31: 0.41666667 | D31: Tekaaibuti | E31: 9 | F31: =IF(Table1333[[#This Row],[Loc ID]]="","",VLOOKUP(Table1333[[#This Row],[Loc ID]],Loc_ID[],2,0)) -> F.Pump & Foam area | G31: Overhead Tank for Fire Pump is needed | H31: Nearmiss | I31: Report as NearMiss | J31: Installation of the overhead tank onsite to address the issue | K31: Maintenance | L31: 45884 | M31: Open | N31: =IF(Table1333[[#This Row],[Date]]="","",(TEXT(Table1333[[#This Row],[Date]],"MMM"))) -> Jul | O31: =IF(Table1333[[#This Row],[Target Date]]="","",(TEXT(Table1333[[#This Row],[Target Date]],"MMM"))) -> Aug
A32: =IF((Table1333[[#This Row],[Date]]=""),"",ROW(A29)) -> 29 | B32: 45836 | C32: 0.41666667 | D32: Tetabo | E32: 1 | F32: =IF(Table1333[[#This Row],[Loc ID]]="","",VLOOKUP(Table1333[[#This Row],[Loc ID]],Loc_ID[],2,0)) -> Operation Office Area | G32: Operations Kitchen is needed to avoid eating at Ops Office | H32: Nearmiss | I32: Report as NearMiss | J32: MOC is required | K32: OM/OS | L32: 45900 | M32: Open | N32: =IF(Table1333[[#This Row],[Date]]="","",(TEXT(Table1333[[#This Row],[Date]],"MMM"))) -> Jun | O32: =IF(Table1333[[#This Row],[Target Date]]="","",(TEXT(Table1333[[#This Row],[Target Date]],"MMM"))) -> Aug
A33: =IF((Table1333[[#This Row],[Date]]=""),"",ROW(A30)) -> 30 | B33: 45836 | C33: 0.48611111 | D33: Tiare | E33: 10 | F33: =IF(Table1333[[#This Row],[Loc ID]]="","",VLOOKUP(Table1333[[#This Row],[Loc ID]],Loc_ID[],2,0)) -> Nmanifold & Pump Shed | G33: ULP Pump impeller is leaking and housing needs installation | H33: Nearmiss | I33: Report as NearMiss | J33: Fitters to take immediate action to avoid ulp leakage and exposure | K33: Fitters | L33: 45845 | M33: Closed | N33: =IF(Table1333[[#This Row],[Date]]="","",(TEXT(Table1333[[#This Row],[Date]],"MMM"))) -> Jun | O33: =IF(Table1333[[#This Row],[Target Date]]="","",(TEXT(Table1333[[#This Row],[Target Date]],"MMM"))) -> Jul
A34: =IF((Table1333[[#This Row],[Date]]=""),"",ROW(A31)) -> 31 | B34: 45837 | C34: 0.42361111 | D34: Tiare | E34: 1 | F34: =IF(Table1333[[#This Row],[Loc ID]]="","",VLOOKUP(Table1333[[#This Row],[Loc ID]],Loc_ID[],2,0)) -> Operation Office Area | G34: Lights needs to be installed at Operations Locker Room | H34: Nearmiss | I34: Report as NearMiss | J34: Procurement and installation of light to designated area | K34: OM/OS | L34: 45869 | M34: Open | N34: =IF(Table1333[[#This Row],[Date]]="","",(TEXT(Table1333[[#This Row],[Date]],"MMM"))) -> Jun | O34: =IF(Table1333[[#This Row],[Target Date]]="","",(TEXT(Table1333[[#This Row],[Target Date]],"MMM"))) -> Jul
A35: =IF((Table1333[[#This Row],[Date]]=""),"",ROW(A32)) -> 32 | B35: 45839 | C35: 0.42361111 | D35: Tiare | E35: 1 | F35: =IF(Table1333[[#This Row],[Loc ID]]="","",VLOOKUP(Table1333[[#This Row],[Loc ID]],Loc_ID[],2,0)) -> Operation Office Area | G35: NTF Security Lights were not working | H35: Nearmiss | I35: Report as NearMiss | J35: to fix asap | K35: OM | L35: 45845 | M35: Closed | N35: =IF(Table1333[[#This Row],[Date]]="","",(TEXT(Table1333[[#This Row],[Date]],"MMM"))) -> Jul | O35: =IF(Table1333[[#This Row],[Target Date]]="","",(TEXT(Table1333[[#This Row],[Target Date]],"MMM"))) -> Jul
A36: =IF((Table1333[[#This Row],[Date]]=""),"",ROW(A33)) -> 33 | B36: 45838 | C36: 0.41666667 | D36: Tibemita | E36: 0.3 | F36: =IF(Table1333[[#This Row],[Loc ID]]="","",VLOOKUP(Table1333[[#This Row],[Loc ID]],Loc_ID[],2,0)) -> Delivery Vehicles | G36: 4084 Hose Tray needs to be fixed | H36: Nearmiss | I36: Report as NearMiss | J36: Installation of hose trays is recommeded | K36: Fitters | L36: 45858 | M36: Open | N36: =IF(Table1333[[#This Row],[Date]]="","",(TEXT(Table1333[[#This Row],[Date]],"MMM"))) -> Jun | O36: =IF(Table1333[[#This Row],[Target Date]]="","",(TEXT(Table1333[[#This Row],[Target Date]],"MMM"))) -> Jul
A37: =IF((Table1333[[#This Row],[Date]]=""),"",ROW(A34)) -> 34 | B37: 45828 | C37: 0.41666667 | D37: Tiiroa | E37: 3 | F37: =IF(Table1333[[#This Row],[Loc ID]]="","",VLOOKUP(Table1333[[#This Row],[Loc ID]],Loc_ID[],2,0)) -> DFS,TTFS area | G37: Old TTFS post are heavily corroded | H37: Nearmiss | I37: Report as NearMiss | J37: Repair and Maintenance is required | K37: Maintenance | L37: 45922 | M37: Open | N37: =IF(Table1333[[#This Row],[Date]]="","",(TEXT(Table1333[[#This Row],[Date]],"MMM"))) -> Jun | O37: =IF(Table1333[[#This Row],[Target Date]]="","",(TEXT(Table1333[[#This Row],[Target Date]],"MMM"))) -> Sep
A38: =IF((Table1333[[#This Row],[Date]]=""),"",ROW(A35)) -> 35 | B38: 45836 | C38: 0.41666667 | D38: Tiiroa | E38: 7 | F38: =IF(Table1333[[#This Row],[Loc ID]]="","",VLOOKUP(Table1333[[#This Row],[Loc ID]],Loc_ID[],2,0)) -> O.TF | G38: Tank 2 Foundation is heavily invaded by plantations | H38: Nearmiss | I38: Report as NearMiss | J38: Removing vegetation around tank 2 base | K38: Maintenance | L38: 45858 | M38: Closed | N38: =IF(Table1333[[#This Row],[Date]]="","",(TEXT(Table1333[[#This Row],[Date]],"MMM"))) -> Jun | O38: =IF(Table1333[[#This Row],[Target Date]]="","",(TEXT(Table1333[[#This Row],[Target Date]],"MMM"))) -> Jul
A39: =IF((Table1333[[#This Row],[Date]]=""),"",ROW(A36)) -> 36 | B39: 45836 | C39: 0.48611111 | D39: Tiiroa | E39: 0.1 | F39: =IF(Table1333[[#This Row],[Loc ID]]="","",VLOOKUP(Table1333[[#This Row],[Loc ID]],Loc_ID[],2,0)) -> Tools & Equipment | G39: Maintenance on valves needed | H39: Nearmiss | I39: Report as NearMiss | J39: derust are repaint corroded valvles | K39: Maintenance | L39: 45869 | M39: Open | N39: =IF(Table1333[[#This Row],[Date]]="","",(TEXT(Table1333[[#This Row],[Date]],"MMM"))) -> Jun | O39: =IF(Table1333[[#This Row],[Target Date]]="","",(TEXT(Table1333[[#This Row],[Target Date]],"MMM"))) -> Jul
... A45: =IF((Table1333[[#This Row],[Date]]=""),"",ROW(A42)) -> 42 | B45: 45845 | C45: 0.41666667 | D45: Tukuaho | E45: 3 | F45: =IF(Table1333[[#This Row],[Loc ID]]="","",VLOOKUP(Table1333[[#This Row],[Loc ID]],Loc_ID[],2,0)) -> DFS,TTFS area | G45: A hole next TTFS is becoming a risk to staff and vehicles | H45: Nearmiss | I45: Report as NearMiss | J45: To cover up the hole or barricade the area for hazard visibility | K45: Maintenance | L45: 45858 | M45: Open | N45: =IF(Table1333[[#This Row],[Date]]="","",(TEXT(Table1333[[#This Row],[Date]],"MMM"))) -> Jul | O45: =IF(Table1333[[#This Row],[Target Date]]="","",(TEXT(Table1333[[#This Row],[Target Date]],"MMM"))) -> Jul
A46: =IF((Table1333[[#This Row],[Date]]=""),"",ROW(A43)) -> 43 | B46: 45839 | C46: 0.70833333 | D46: Tukuaho | E46: 11 | F46: =IF(Table1333[[#This Row],[Loc ID]]="","",VLOOKUP(Table1333[[#This Row],[Loc ID]],Loc_ID[],2,0)) -> TTFS and Drums Area | N46: =IF(Table1333[[#This Row],[Date]]="","",(TEXT(Table1333[[#This Row],[Date]],"MMM"))) -> Jul | O46: =IF(Table1333[[#This Row],[Target Date]]="","",(TEXT(Table1333[[#This Row],[Target Date]],"MMM")))
A47: =IF((Table1333[[#This Row],[Date]]=""),"",ROW(A44)) -> 44 | B47: 45845 | C47: 0.64583333 | D47: William | E47: 1 | F47: =IF(Table1333[[#This Row],[Loc ID]]="","",VLOOKUP(Table1333[[#This Row],[Loc ID]],Loc_ID[],2,0)) -> Operation Office Area | G47: Petrol car entered the KOIL compound without knowing the rules | H47: Nearmiss | I47: Immediately inform the driver and warn him about the safety rules | J47: A proper safety display to be placed at the gate for Customers information | K47: HSSEF | L47: 45894 | M47: Closed | N47: =IF(Table1333[[#This Row],[Date]]="","",(TEXT(Table1333[[#This Row],[Date]],"MMM"))) -> Jul | O47: =IF(Table1333[[#This Row],[Target Date]]="","",(TEXT(Table1333[[#This Row],[Target Date]],"MMM"))) -> Aug
A48: =IF((Table1333[[#This Row],[Date]]=""),"",ROW(A45)) -> 45 | B48: 45839 | C48: 0.89583333 | D48: Tiare | E48: 5 | F48: =IF(Table1333[[#This Row],[Loc ID]]="","",VLOOKUP(Table1333[[#This Row],[Loc ID]],Loc_ID[],2,0)) -> Lube Shed Area & Lab area | G48: Lab light not fully operational and impair visual during testing | H48: Nearmiss | I48: Report in Tool Box | J48: Repair and Maintenance is required | K48: Maintenance | L48: 45853 | M48: Open | N48: =IF(Table1333[[#This Row],[Date]]="","",(TEXT(Table1333[[#This Row],[Date]],"MMM"))) -> Jul | O48: =IF(Table1333[[#This Row],[Target Date]]="","",(TEXT(Table1333[[#This Row],[Target Date]],"MMM"))) -> Jul
A49: =IF((Table1333[[#This Row],[Date]]=""),"",ROW(A46)) -> 46 | B49: 45839 | C49: 0.43055556 | D49: Aratite | E49: 3 | F49: =IF(Table1333[[#This Row],[Loc ID]]="","",VLOOKUP(Table1333[[#This Row],[Loc ID]],Loc_ID[],2,0)) -> DFS,TTFS area | G49: Direct refilling of tanker truck bypassing a deadman valve which can cause major spills when one is unconciously idle. | H49: Nearmiss | I49: Report as NearMiss | J49: Connecting through the deadman valve is recommended | K49: Fitters | L49: 45868 | M49: Open | N49: =IF(Table1333[[#This Row],[Date]]="","",(TEXT(Table1333[[#This Row],[Date]],"MMM"))) -> Jul | O49: =IF(Table1333[[#This Row],[Target Date]]="","",(TEXT(Table1333[[#This Row],[Target Date]],"MMM"))) -> Jul
A50: =IF((Table1333[[#This Row],[Date]]=""),"",ROW(A47)) -> 47 | B50: 45839 | C50: 0.43055556 | D50: Aratite | E50: 1 | F50: =IF(Table1333[[#This Row],[Loc ID]]="","",VLOOKUP(Table1333[[#This Row],[Loc ID]],Loc_ID[],2,0)) -> Operation Office Area | G50: Damage slab at the main gate entry, where the mesh wire popped up, and very risky to the public and also for vehicles' tires can eventually be punctured by | H50: Nearmiss | I50: Report as NearMiss | J50: Repair on the slab on this finding to avoid such risk | K50: Maintenance | L50: 45868 | M50: Closed | N50: =IF(Table1333[[#This Row],[Date]]="","",(TEXT(Table1333[[#This Row],[Date]],"MMM"))) -> Jul | O50: =IF(Table1333[[#This Row],[Target Date]]="","",(TEXT(Table1333[[#This Row],[Target Date]],"MMM"))) -> Jul
...

Sheet IR
A1: Ref No | B1: Date | C1: Reporter | D1: Type | E1: Location | F1: Description | G1: Root Cause | H1: Impact | I1: Action Taken | J1: Recommendations
A2: C001 | B2: 45664 | C2: Tatang Tataua | D2: Vehicle Collision | E2: KFL driving road to the dock site | F2: Pneumatic system failure, poor road conditions causing collision. | G2: Pneumatic system failure, poor road conditions | H2: Scratches, bumper detached on saloon car | I2: Maintenance review, safety protocol updates, vehicle reassessment | J2: Maintenance review, safety protocol updates, vehicle reassessment
A3: D001 | B3: 46012 | C3: Kararaua Temarebu | D3: Death | E3: KOIL, in front of storeroom next to canteen, Betio | F3: Victim fell into a bore well while intoxicated after an event. | G3: Intoxication, unsafe area | H3: Death | I3: Police investigation ongoing | J3: Safety measures around bore wells
A4: OF001v1 | B4: 45737 | C4: Tatang Tataua | D4: Fuel Overflow | E4: Tanker Loading Area | F4: ULP mistakenly loaded into Diesel-filled compartment, causing overflow. | G4: Inexperience, lack of supervision, protocol not followed | H4: 40L to 60L spill | I4: Contaminated mix transferred for recovery | J4: Supervision and training improvements
A5: PL001 | B5: 45711 | C5: Kakianako / TDO | D5: Diesel Pipeline Leak | E5: Underground line near KFL premises | F5: Diesel leak from pipeline into seawall drainage | G5: Old pipeline, lack of maintenance | H5: Environmental damage | I5: Stopped ops, flushed line, marine spill response | J5: Replace old pipeline, train staff, upgrade infra
A6: SC001 | B6: 45800 | C6: Teinamotuna | D6: Electrical Short | E6: LPG rest area next to refilling station | F6: Short circuit at power point/plug for AC | G6: Poor wiring, unsafe plug | H6: Explosion, Fatality risk | I6: Power isolated, reported to technicians | J6: Relocate power point or remove electricity entirely
A7: SPC1-25 | B7: 45744 | C7: Teinamotuna | D7: Safety Performance Counseling | E7: Near LPG Station / Gas Stations | F7: - Entered LPG area without PPE- Used phone while unloading at gas station | G7: Non-compliance due to wet uniform & awareness gap | I7: Counseling conducted; Nawaia committed to compliance | J7: Follow PPE policy strictly; reinforce phone-use rules
A8: TL001 | B8: 45698 | C8: Mareti Akai (Security) | D8: Tank Leakage | E8: Tank 2 (Facing Admin Office) | F8: Leak at drain valve and tank base. | G8: Tank deterioration; water layer depleted. | H8: Fuel spill; stock loss risk. | I8: Leak monitored, area secured, maintenance alerted. | J8: Refurbish tank; refill water displacement; regular checks.
A9: TL002 | B9: 45747 | C9: Security | D9: Tank Leakage (Repeat) | E9: Tank 2 (Facing Admin Office) | F9: The leak continues to be observed | G9: Unsafe condition, unsafe facility | H9: Continuous contamination and product loss | I9: Tank cleaning and repairs | J9: Refurbish tank base; replace valve; retighten manhole.
A10: TL003 | B10: 45800 | C10: Mareti Akai (Security) | D10: Tank Leakage (Repeat) | E10: Tank 2 (Facing Admin Office) | F10: Leak reoccurred despite earlier maintenance. | G10: Failed repair; dry water layer; loose manhole. | H10: Underground contamination; continued stock loss. | I10: Area secured; damage assessed; maintenance notified. | J10: SSC recommends to demolish or to stop using the tank.
A11: FF001 | B11: 45892 | C11: HRM | D11: Fall from height | E11: Tank 1 | F11: Mr. Buranibeia Kaumai fell from scaffolding (~4–5m high) while cutting tank shell sheets during demolition work. Wind pushed the sheet outward, causing panic and loss of balance. He was not wearing a harness. | G11: Failure to wear safety harness; reaction to wind movement of sheet; loss of balance; fall from scaffold. | H11: Injury requiring hospital treatment; transported to Betio and then Nawerewere Hospital for x-ray. | I11: Work stopped immediately; first aid provided; ambulance arrived within 10 minutes; victim transported and treated; witnesses confirmed he was conscious and moving normally. | J11: Enforce harness use at all heights; promote safety culture via toolbox talks; ensure compliance with Work Permit conditions through supervisor monitoring.

Sheet EI
A1: KOIL LOD3 Electical Inspections
A2: Date Conducted: 10-15 March 2025 Inspector: Maeke Tabuaka
A3: Item | B3: Site | C3: Location | D3: Inspection | E3: Description | F3: Recommendation | G3: Status
A4: 1 | B4: BET | C4: Operation & Admin Office | D4: Office Switch Boards Loads | E4: Red phase: 57A Yellow phase: 66A Blue phase: 49A | F4: Okay
A5: 2 | B5: Bon | C5: KOIL Office | D5: Office Switch Boards Loads | E5: Single-phase system, 30A reading | F5: Okay
A6: 3 | B6: BET | C6: Admin and Operation office | D6: Wiring System | E6: Betio office require new seals or conduits Signs of aging and non-compliant installations were observed | F6: Install new seals and conduits where needed Upgrade wiring to meet current electrical safety standards
A7: 4 | B7: BET/BON | C7: 1. Main Switch Board (Backup Gen. Area) 2. Operation office main switch board 3. Bonriki Main Switch Board | D7: Heath & Safety | E7: Both Betio and Bonriki offices have uncovered electrical switchboards Live wires exposed in the main distribution box — poses significant electric shock and fire hazards. | F7: Replace or properly cover the distribution boxes and switchboards at both sites. Immediate renewal and rectification are strongly advised to ensure safety compliance.
A8: 5 | B8: BET | C8: Old Tank Farm (Tk2,3,4) | D8: Grounding/Earthing | E8: -Most buildings, machines, pumps, and fuel tanks have no earth wiring. - Some grounding connections were found to be disconnected. | F8: Install or reconnect earth wires on all applicable equipment and structures. Conduct a full grounding test after corrections are made.

Sheet Audit Logs
A1: # | B1: Audit Date | C1: Audit Type | D1: Auditor(s) | E1: Location/Area | F1: Department | G1: Status | H1: Remarks
A2: 1 | B2: 45731 | C2: LOD3. E.Insp | D2: Maeke | E2: BET/BON | F2: Workshop | G2: Completed | H2: All PPE compliant
A3: 2 | B3: 45792 | C3: Pre-Audit | D3: Maareke | E3: BON | F3: Aviation | G3: Completed
A4: 3 | B4: 45793 | C4: CAAK | D4: Javir | E4: BET/BON | F4: HSSE&OP | G4: Completed | H4: Training & Calibrations
A5: 4 | B5: 45806 | C5: HSSE | D5: Maareke | E5: BET | F5: Operations | G5: Completed | H5: Need more awareness and safety precaution
A6: 5 | B6: 45818 | C6: SSWB | D6: SSC | E6: BET | F6: HSSE | G6: Completed | H6: Follow-up needed

Sheet TR

Sheet L.ID
A1: Loc ID | B1: Description
A2: 1 | B2: Operation Office Area
A3: 1.1 | B3: Operation Fence&Perimeter
A4: 2 | B4: LPG & Cashier Area
A5: 2.1 | B5: LPG & Cashier Area Perimeter
A6: 3 | B6: DFS,TTFS area
A7: 4 | B7: WasteOil&Separator Area
A8: 5 | B8: Lube Shed Area & Lab area
A9: 6 | B9: O.Pump
A10: 7 | B10: O.TF
A11: 8 | B11: O.Manifold
A12: 9 | B12: F.Pump & Foam area
A13: 10 | B13: Nmanifold & Pump Shed
... A30: 0.3 | B30: Delivery Vehicles
A31: 0.3a | B31: Vehicles & Transportation
A32: 0.4 | B32: Compliance
A33: 0.5 | B33: Procedures
